{"time":"2023-07-04 04:48:54","level":"INFO","module":"__init__","method":"__init__","line":264,"path":"C:\\Users\\yunus\\anaconda3\\lib\\site-packages\\anaconda_navigator\\widgets\\main_window\\__init__.py","message":"appusermodelid: 0"}
{"time":"2023-07-04 04:48:57","level":"ERROR","module":"pool","method":"__fetch_configuration","line":238,"path":"C:\\Users\\yunus\\anaconda3\\lib\\site-packages\\anaconda_navigator\\utils\\attribution\\pool.py","message":"failed to initialize advertisement","exception":"Traceback (most recent call last):\n  File \"C:\\Users\\yunus\\anaconda3\\lib\\site-packages\\anaconda_navigator\\utils\\attribution\\pool.py\", line 212, in __fetch_configuration\n    'advertisements': json.loads(advertisement_content),\n  File \"C:\\Users\\yunus\\anaconda3\\lib\\json\\__init__.py\", line 346, in loads\n    return _default_decoder.decode(s)\n  File \"C:\\Users\\yunus\\anaconda3\\lib\\json\\decoder.py\", line 337, in decode\n    obj, end = self.raw_decode(s, idx=_w(s, 0).end())\n  File \"C:\\Users\\yunus\\anaconda3\\lib\\json\\decoder.py\", line 355, in raw_decode\n    raise JSONDecodeError(\"Expecting value\", s, err.value) from None\njson.decoder.JSONDecodeError: Expecting value: line 1 column 1 (char 0)"}
{"time":"2023-07-04 04:48:58","level":"ERROR","module":"pool","method":"__fetch_configuration","line":238,"path":"C:\\Users\\yunus\\anaconda3\\lib\\site-packages\\anaconda_navigator\\utils\\attribution\\pool.py","message":"failed to initialize advertisement","exception":"Traceback (most recent call last):\n  File \"C:\\Users\\yunus\\anaconda3\\lib\\site-packages\\anaconda_navigator\\utils\\attribution\\pool.py\", line 212, in __fetch_configuration\n    'advertisements': json.loads(advertisement_content),\n  File \"C:\\Users\\yunus\\anaconda3\\lib\\json\\__init__.py\", line 346, in loads\n    return _default_decoder.decode(s)\n  File \"C:\\Users\\yunus\\anaconda3\\lib\\json\\decoder.py\", line 337, in decode\n    obj, end = self.raw_decode(s, idx=_w(s, 0).end())\n  File \"C:\\Users\\yunus\\anaconda3\\lib\\json\\decoder.py\", line 355, in raw_decode\n    raise JSONDecodeError(\"Expecting value\", s, err.value) from None\njson.decoder.JSONDecodeError: Expecting value: line 1 column 1 (char 0)"}
{"time":"2023-07-04 04:49:07","level":"INFO","module":"__init__","method":"setup","line":473,"path":"C:\\Users\\yunus\\anaconda3\\lib\\site-packages\\anaconda_navigator\\widgets\\main_window\\__init__.py","message":"Initial setup"}
{"time":"2023-07-04 09:25:45","level":"INFO","module":"__init__","method":"__init__","line":264,"path":"C:\\Users\\yunus\\anaconda3\\lib\\site-packages\\anaconda_navigator\\widgets\\main_window\\__init__.py","message":"appusermodelid: 0"}
{"time":"2023-07-04 09:25:47","level":"ERROR","module":"pool","method":"__fetch_configuration","line":238,"path":"C:\\Users\\yunus\\anaconda3\\lib\\site-packages\\anaconda_navigator\\utils\\attribution\\pool.py","message":"failed to initialize advertisement","exception":"Traceback (most recent call last):\n  File \"C:\\Users\\yunus\\anaconda3\\lib\\site-packages\\anaconda_navigator\\utils\\attribution\\pool.py\", line 212, in __fetch_configuration\n    'advertisements': json.loads(advertisement_content),\n  File \"C:\\Users\\yunus\\anaconda3\\lib\\json\\__init__.py\", line 346, in loads\n    return _default_decoder.decode(s)\n  File \"C:\\Users\\yunus\\anaconda3\\lib\\json\\decoder.py\", line 337, in decode\n    obj, end = self.raw_decode(s, idx=_w(s, 0).end())\n  File \"C:\\Users\\yunus\\anaconda3\\lib\\json\\decoder.py\", line 355, in raw_decode\n    raise JSONDecodeError(\"Expecting value\", s, err.value) from None\njson.decoder.JSONDecodeError: Expecting value: line 1 column 1 (char 0)"}
{"time":"2023-07-04 09:25:48","level":"ERROR","module":"pool","method":"__fetch_configuration","line":238,"path":"C:\\Users\\yunus\\anaconda3\\lib\\site-packages\\anaconda_navigator\\utils\\attribution\\pool.py","message":"failed to initialize advertisement","exception":"Traceback (most recent call last):\n  File \"C:\\Users\\yunus\\anaconda3\\lib\\site-packages\\anaconda_navigator\\utils\\attribution\\pool.py\", line 212, in __fetch_configuration\n    'advertisements': json.loads(advertisement_content),\n  File \"C:\\Users\\yunus\\anaconda3\\lib\\json\\__init__.py\", line 346, in loads\n    return _default_decoder.decode(s)\n  File \"C:\\Users\\yunus\\anaconda3\\lib\\json\\decoder.py\", line 337, in decode\n    obj, end = self.raw_decode(s, idx=_w(s, 0).end())\n  File \"C:\\Users\\yunus\\anaconda3\\lib\\json\\decoder.py\", line 355, in raw_decode\n    raise JSONDecodeError(\"Expecting value\", s, err.value) from None\njson.decoder.JSONDecodeError: Expecting value: line 1 column 1 (char 0)"}
{"time":"2023-07-04 09:25:52","level":"INFO","module":"__init__","method":"setup","line":473,"path":"C:\\Users\\yunus\\anaconda3\\lib\\site-packages\\anaconda_navigator\\widgets\\main_window\\__init__.py","message":"Initial setup"}
{"time":"2023-07-05 03:30:45","level":"INFO","module":"__init__","method":"__init__","line":264,"path":"C:\\Users\\yunus\\anaconda3\\lib\\site-packages\\anaconda_navigator\\widgets\\main_window\\__init__.py","message":"appusermodelid: 0"}
{"time":"2023-07-05 03:30:48","level":"ERROR","module":"pool","method":"__fetch_configuration","line":238,"path":"C:\\Users\\yunus\\anaconda3\\lib\\site-packages\\anaconda_navigator\\utils\\attribution\\pool.py","message":"failed to initialize advertisement","exception":"Traceback (most recent call last):\n  File \"C:\\Users\\yunus\\anaconda3\\lib\\site-packages\\anaconda_navigator\\utils\\attribution\\pool.py\", line 212, in __fetch_configuration\n    'advertisements': json.loads(advertisement_content),\n  File \"C:\\Users\\yunus\\anaconda3\\lib\\json\\__init__.py\", line 346, in loads\n    return _default_decoder.decode(s)\n  File \"C:\\Users\\yunus\\anaconda3\\lib\\json\\decoder.py\", line 337, in decode\n    obj, end = self.raw_decode(s, idx=_w(s, 0).end())\n  File \"C:\\Users\\yunus\\anaconda3\\lib\\json\\decoder.py\", line 355, in raw_decode\n    raise JSONDecodeError(\"Expecting value\", s, err.value) from None\njson.decoder.JSONDecodeError: Expecting value: line 1 column 1 (char 0)"}
{"time":"2023-07-05 03:30:49","level":"ERROR","module":"pool","method":"__fetch_configuration","line":238,"path":"C:\\Users\\yunus\\anaconda3\\lib\\site-packages\\anaconda_navigator\\utils\\attribution\\pool.py","message":"failed to initialize advertisement","exception":"Traceback (most recent call last):\n  File \"C:\\Users\\yunus\\anaconda3\\lib\\site-packages\\anaconda_navigator\\utils\\attribution\\pool.py\", line 212, in __fetch_configuration\n    'advertisements': json.loads(advertisement_content),\n  File \"C:\\Users\\yunus\\anaconda3\\lib\\json\\__init__.py\", line 346, in loads\n    return _default_decoder.decode(s)\n  File \"C:\\Users\\yunus\\anaconda3\\lib\\json\\decoder.py\", line 337, in decode\n    obj, end = self.raw_decode(s, idx=_w(s, 0).end())\n  File \"C:\\Users\\yunus\\anaconda3\\lib\\json\\decoder.py\", line 355, in raw_decode\n    raise JSONDecodeError(\"Expecting value\", s, err.value) from None\njson.decoder.JSONDecodeError: Expecting value: line 1 column 1 (char 0)"}
{"time":"2023-07-05 03:30:54","level":"INFO","module":"__init__","method":"setup","line":473,"path":"C:\\Users\\yunus\\anaconda3\\lib\\site-packages\\anaconda_navigator\\widgets\\main_window\\__init__.py","message":"Initial setup"}
{"time":"2023-07-06 04:40:31","level":"INFO","module":"__init__","method":"__init__","line":264,"path":"C:\\Users\\yunus\\anaconda3\\lib\\site-packages\\anaconda_navigator\\widgets\\main_window\\__init__.py","message":"appusermodelid: 0"}
{"time":"2023-07-06 04:40:33","level":"ERROR","module":"pool","method":"__fetch_configuration","line":238,"path":"C:\\Users\\yunus\\anaconda3\\lib\\site-packages\\anaconda_navigator\\utils\\attribution\\pool.py","message":"failed to initialize advertisement","exception":"Traceback (most recent call last):\n  File \"C:\\Users\\yunus\\anaconda3\\lib\\site-packages\\anaconda_navigator\\utils\\attribution\\pool.py\", line 212, in __fetch_configuration\n    'advertisements': json.loads(advertisement_content),\n  File \"C:\\Users\\yunus\\anaconda3\\lib\\json\\__init__.py\", line 346, in loads\n    return _default_decoder.decode(s)\n  File \"C:\\Users\\yunus\\anaconda3\\lib\\json\\decoder.py\", line 337, in decode\n    obj, end = self.raw_decode(s, idx=_w(s, 0).end())\n  File \"C:\\Users\\yunus\\anaconda3\\lib\\json\\decoder.py\", line 355, in raw_decode\n    raise JSONDecodeError(\"Expecting value\", s, err.value) from None\njson.decoder.JSONDecodeError: Expecting value: line 1 column 1 (char 0)"}
{"time":"2023-07-06 04:40:34","level":"ERROR","module":"pool","method":"__fetch_configuration","line":238,"path":"C:\\Users\\yunus\\anaconda3\\lib\\site-packages\\anaconda_navigator\\utils\\attribution\\pool.py","message":"failed to initialize advertisement","exception":"Traceback (most recent call last):\n  File \"C:\\Users\\yunus\\anaconda3\\lib\\site-packages\\anaconda_navigator\\utils\\attribution\\pool.py\", line 212, in __fetch_configuration\n    'advertisements': json.loads(advertisement_content),\n  File \"C:\\Users\\yunus\\anaconda3\\lib\\json\\__init__.py\", line 346, in loads\n    return _default_decoder.decode(s)\n  File \"C:\\Users\\yunus\\anaconda3\\lib\\json\\decoder.py\", line 337, in decode\n    obj, end = self.raw_decode(s, idx=_w(s, 0).end())\n  File \"C:\\Users\\yunus\\anaconda3\\lib\\json\\decoder.py\", line 355, in raw_decode\n    raise JSONDecodeError(\"Expecting value\", s, err.value) from None\njson.decoder.JSONDecodeError: Expecting value: line 1 column 1 (char 0)"}
{"time":"2023-07-06 04:40:41","level":"INFO","module":"__init__","method":"setup","line":473,"path":"C:\\Users\\yunus\\anaconda3\\lib\\site-packages\\anaconda_navigator\\widgets\\main_window\\__init__.py","message":"Initial setup"}
{"time":"2023-07-07 03:50:54","level":"INFO","module":"__init__","method":"__init__","line":264,"path":"C:\\Users\\yunus\\anaconda3\\lib\\site-packages\\anaconda_navigator\\widgets\\main_window\\__init__.py","message":"appusermodelid: 0"}
{"time":"2023-07-07 03:51:06","level":"INFO","module":"__init__","method":"setup","line":473,"path":"C:\\Users\\yunus\\anaconda3\\lib\\site-packages\\anaconda_navigator\\widgets\\main_window\\__init__.py","message":"Initial setup"}
{"time":"2023-07-08 00:47:16","level":"INFO","module":"__init__","method":"__init__","line":264,"path":"C:\\Users\\yunus\\anaconda3\\lib\\site-packages\\anaconda_navigator\\widgets\\main_window\\__init__.py","message":"appusermodelid: 0"}
{"time":"2023-07-08 00:47:25","level":"INFO","module":"__init__","method":"setup","line":473,"path":"C:\\Users\\yunus\\anaconda3\\lib\\site-packages\\anaconda_navigator\\widgets\\main_window\\__init__.py","message":"Initial setup"}
{"time":"2023-07-09 03:42:57","level":"INFO","module":"__init__","method":"__init__","line":264,"path":"C:\\Users\\yunus\\anaconda3\\lib\\site-packages\\anaconda_navigator\\widgets\\main_window\\__init__.py","message":"appusermodelid: 0"}
{"time":"2023-07-09 03:43:10","level":"INFO","module":"__init__","method":"setup","line":473,"path":"C:\\Users\\yunus\\anaconda3\\lib\\site-packages\\anaconda_navigator\\widgets\\main_window\\__init__.py","message":"Initial setup"}
{"time":"2023-07-09 09:42:04","level":"INFO","module":"__init__","method":"__init__","line":264,"path":"C:\\Users\\yunus\\anaconda3\\lib\\site-packages\\anaconda_navigator\\widgets\\main_window\\__init__.py","message":"appusermodelid: 0"}
{"time":"2023-07-09 09:42:12","level":"INFO","module":"__init__","method":"setup","line":473,"path":"C:\\Users\\yunus\\anaconda3\\lib\\site-packages\\anaconda_navigator\\widgets\\main_window\\__init__.py","message":"Initial setup"}
{"time":"2023-07-09 09:42:16","level":"ERROR","module":"resources","method":"load_resource","line":30,"path":"C:\\Users\\yunus\\anaconda3\\lib\\site-packages\\anaconda_navigator\\utils\\attribution\\resources.py","message":"Unable to fetch resource: https:\/\/anaconda.cloud\/api\/billboard\/v1\/ads\/navigator","exception":"Traceback (most recent call last):\n  File \"C:\\Users\\yunus\\anaconda3\\lib\\site-packages\\urllib3\\connection.py\", line 174, in _new_conn\n    conn = connection.create_connection(\n  File \"C:\\Users\\yunus\\anaconda3\\lib\\site-packages\\urllib3\\util\\connection.py\", line 72, in create_connection\n    for res in socket.getaddrinfo(host, port, family, socket.SOCK_STREAM):\n  File \"C:\\Users\\yunus\\anaconda3\\lib\\socket.py\", line 955, in getaddrinfo\n    for res in _socket.getaddrinfo(host, port, family, type, proto, flags):\nsocket.gaierror: [Errno 11001] getaddrinfo failed\n\nDuring handling of the above exception, another exception occurred:\n\nTraceback (most recent call last):\n  File \"C:\\Users\\yunus\\anaconda3\\lib\\site-packages\\urllib3\\connectionpool.py\", line 703, in urlopen\n    httplib_response = self._make_request(\n  File \"C:\\Users\\yunus\\anaconda3\\lib\\site-packages\\urllib3\\connectionpool.py\", line 386, in _make_request\n    self._validate_conn(conn)\n  File \"C:\\Users\\yunus\\anaconda3\\lib\\site-packages\\urllib3\\connectionpool.py\", line 1042, in _validate_conn\n    conn.connect()\n  File \"C:\\Users\\yunus\\anaconda3\\lib\\site-packages\\urllib3\\connection.py\", line 358, in connect\n    self.sock = conn = self._new_conn()\n  File \"C:\\Users\\yunus\\anaconda3\\lib\\site-packages\\urllib3\\connection.py\", line 186, in _new_conn\n    raise NewConnectionError(\nurllib3.exceptions.NewConnectionError: <urllib3.connection.HTTPSConnection object at 0x0000020941F38550>: Failed to establish a new connection: [Errno 11001] getaddrinfo failed\n\nDuring handling of the above exception, another exception occurred:\n\nTraceback (most recent call last):\n  File \"C:\\Users\\yunus\\anaconda3\\lib\\site-packages\\requests\\adapters.py\", line 489, in send\n    resp = conn.urlopen(\n  File \"C:\\Users\\yunus\\anaconda3\\lib\\site-packages\\urllib3\\connectionpool.py\", line 787, in urlopen\n    retries = retries.increment(\n  File \"C:\\Users\\yunus\\anaconda3\\lib\\site-packages\\urllib3\\util\\retry.py\", line 592, in increment\n    raise MaxRetryError(_pool, url, error or ResponseError(cause))\nurllib3.exceptions.MaxRetryError: HTTPSConnectionPool(host='anaconda.cloud', port=443): Max retries exceeded with url: \/api\/billboard\/v1\/ads\/navigator (Caused by NewConnectionError('<urllib3.connection.HTTPSConnection object at 0x0000020941F38550>: Failed to establish a new connection: [Errno 11001] getaddrinfo failed'))\n\nDuring handling of the above exception, another exception occurred:\n\nTraceback (most recent call last):\n  File \"C:\\Users\\yunus\\anaconda3\\lib\\site-packages\\anaconda_navigator\\utils\\attribution\\resources.py\", line 24, in load_resource\n    response: requests.Response = requests.get(url, timeout=30)\n  File \"C:\\Users\\yunus\\anaconda3\\lib\\site-packages\\requests\\api.py\", line 73, in get\n    return request(\"get\", url, params=params, **kwargs)\n  File \"C:\\Users\\yunus\\anaconda3\\lib\\site-packages\\requests\\api.py\", line 59, in request\n    return session.request(method=method, url=url, **kwargs)\n  File \"C:\\Users\\yunus\\anaconda3\\lib\\site-packages\\requests\\sessions.py\", line 587, in request\n    resp = self.send(prep, **send_kwargs)\n  File \"C:\\Users\\yunus\\anaconda3\\lib\\site-packages\\requests\\sessions.py\", line 701, in send\n    r = adapter.send(request, **kwargs)\n  File \"C:\\Users\\yunus\\anaconda3\\lib\\site-packages\\requests\\adapters.py\", line 565, in send\n    raise ConnectionError(e, request=request)\nrequests.exceptions.ConnectionError: HTTPSConnectionPool(host='anaconda.cloud', port=443): Max retries exceeded with url: \/api\/billboard\/v1\/ads\/navigator (Caused by NewConnectionError('<urllib3.connection.HTTPSConnection object at 0x0000020941F38550>: Failed to establish a new connection: [Errno 11001] getaddrinfo failed'))"}
{"time":"2023-07-09 09:42:27","level":"ERROR","module":"resources","method":"load_resource","line":30,"path":"C:\\Users\\yunus\\anaconda3\\lib\\site-packages\\anaconda_navigator\\utils\\attribution\\resources.py","message":"Unable to fetch resource: https:\/\/assets.anaconda.com\/production\/api\/navigator\/AnacondaNotebooks-LearnMore.png?w=150&auto=compress%2Cformat&fit=crop&dm=1664393318&s=6322df85fa256451d7f52cff7f904370","exception":"Traceback (most recent call last):\n  File \"C:\\Users\\yunus\\anaconda3\\lib\\site-packages\\urllib3\\connection.py\", line 174, in _new_conn\n    conn = connection.create_connection(\n  File \"C:\\Users\\yunus\\anaconda3\\lib\\site-packages\\urllib3\\util\\connection.py\", line 72, in create_connection\n    for res in socket.getaddrinfo(host, port, family, socket.SOCK_STREAM):\n  File \"C:\\Users\\yunus\\anaconda3\\lib\\socket.py\", line 955, in getaddrinfo\n    for res in _socket.getaddrinfo(host, port, family, type, proto, flags):\nsocket.gaierror: [Errno 11001] getaddrinfo failed\n\nDuring handling of the above exception, another exception occurred:\n\nTraceback (most recent call last):\n  File \"C:\\Users\\yunus\\anaconda3\\lib\\site-packages\\urllib3\\connectionpool.py\", line 703, in urlopen\n    httplib_response = self._make_request(\n  File \"C:\\Users\\yunus\\anaconda3\\lib\\site-packages\\urllib3\\connectionpool.py\", line 386, in _make_request\n    self._validate_conn(conn)\n  File \"C:\\Users\\yunus\\anaconda3\\lib\\site-packages\\urllib3\\connectionpool.py\", line 1042, in _validate_conn\n    conn.connect()\n  File \"C:\\Users\\yunus\\anaconda3\\lib\\site-packages\\urllib3\\connection.py\", line 358, in connect\n    self.sock = conn = self._new_conn()\n  File \"C:\\Users\\yunus\\anaconda3\\lib\\site-packages\\urllib3\\connection.py\", line 186, in _new_conn\n    raise NewConnectionError(\nurllib3.exceptions.NewConnectionError: <urllib3.connection.HTTPSConnection object at 0x000002093C3E1630>: Failed to establish a new connection: [Errno 11001] getaddrinfo failed\n\nDuring handling of the above exception, another exception occurred:\n\nTraceback (most recent call last):\n  File \"C:\\Users\\yunus\\anaconda3\\lib\\site-packages\\requests\\adapters.py\", line 489, in send\n    resp = conn.urlopen(\n  File \"C:\\Users\\yunus\\anaconda3\\lib\\site-packages\\urllib3\\connectionpool.py\", line 787, in urlopen\n    retries = retries.increment(\n  File \"C:\\Users\\yunus\\anaconda3\\lib\\site-packages\\urllib3\\util\\retry.py\", line 592, in increment\n    raise MaxRetryError(_pool, url, error or ResponseError(cause))\nurllib3.exceptions.MaxRetryError: HTTPSConnectionPool(host='assets.anaconda.com', port=443): Max retries exceeded with url: \/production\/api\/navigator\/AnacondaNotebooks-LearnMore.png?w=150&auto=compress%2Cformat&fit=crop&dm=1664393318&s=6322df85fa256451d7f52cff7f904370 (Caused by NewConnectionError('<urllib3.connection.HTTPSConnection object at 0x000002093C3E1630>: Failed to establish a new connection: [Errno 11001] getaddrinfo failed'))\n\nDuring handling of the above exception, another exception occurred:\n\nTraceback (most recent call last):\n  File \"C:\\Users\\yunus\\anaconda3\\lib\\site-packages\\anaconda_navigator\\utils\\attribution\\resources.py\", line 24, in load_resource\n    response: requests.Response = requests.get(url, timeout=30)\n  File \"C:\\Users\\yunus\\anaconda3\\lib\\site-packages\\requests\\api.py\", line 73, in get\n    return request(\"get\", url, params=params, **kwargs)\n  File \"C:\\Users\\yunus\\anaconda3\\lib\\site-packages\\requests\\api.py\", line 59, in request\n    return session.request(method=method, url=url, **kwargs)\n  File \"C:\\Users\\yunus\\anaconda3\\lib\\site-packages\\requests\\sessions.py\", line 587, in request\n    resp = self.send(prep, **send_kwargs)\n  File \"C:\\Users\\yunus\\anaconda3\\lib\\site-packages\\requests\\sessions.py\", line 701, in send\n    r = adapter.send(request, **kwargs)\n  File \"C:\\Users\\yunus\\anaconda3\\lib\\site-packages\\requests\\adapters.py\", line 565, in send\n    raise ConnectionError(e, request=request)\nrequests.exceptions.ConnectionError: HTTPSConnectionPool(host='assets.anaconda.com', port=443): Max retries exceeded with url: \/production\/api\/navigator\/AnacondaNotebooks-LearnMore.png?w=150&auto=compress%2Cformat&fit=crop&dm=1664393318&s=6322df85fa256451d7f52cff7f904370 (Caused by NewConnectionError('<urllib3.connection.HTTPSConnection object at 0x000002093C3E1630>: Failed to establish a new connection: [Errno 11001] getaddrinfo failed'))"}
{"time":"2023-07-09 09:42:30","level":"ERROR","module":"client_api","method":"_get_api_info","line":648,"path":"C:\\Users\\yunus\\anaconda3\\lib\\site-packages\\anaconda_navigator\\api\\client_api.py","message":"HTTPSConnectionPool(host='api.anaconda.org', port=443): Max retries exceeded with url: \/ (Caused by NewConnectionError('<urllib3.connection.HTTPSConnection object at 0x000002093EE5A950>: Failed to establish a new connection: [Errno 11001] getaddrinfo failed'))"}
{"time":"2023-07-10 04:13:12","level":"INFO","module":"__init__","method":"__init__","line":264,"path":"C:\\Users\\yunus\\anaconda3\\lib\\site-packages\\anaconda_navigator\\widgets\\main_window\\__init__.py","message":"appusermodelid: 0"}
{"time":"2023-07-10 04:13:21","level":"INFO","module":"__init__","method":"setup","line":473,"path":"C:\\Users\\yunus\\anaconda3\\lib\\site-packages\\anaconda_navigator\\widgets\\main_window\\__init__.py","message":"Initial setup"}
{"time":"2023-07-10 10:37:13","level":"INFO","module":"__init__","method":"__init__","line":264,"path":"C:\\Users\\yunus\\anaconda3\\lib\\site-packages\\anaconda_navigator\\widgets\\main_window\\__init__.py","message":"appusermodelid: 0"}
{"time":"2023-07-10 10:37:21","level":"INFO","module":"__init__","method":"setup","line":473,"path":"C:\\Users\\yunus\\anaconda3\\lib\\site-packages\\anaconda_navigator\\widgets\\main_window\\__init__.py","message":"Initial setup"}
{"time":"2023-07-11 02:22:57","level":"INFO","module":"__init__","method":"__init__","line":264,"path":"C:\\Users\\yunus\\anaconda3\\lib\\site-packages\\anaconda_navigator\\widgets\\main_window\\__init__.py","message":"appusermodelid: 0"}
{"time":"2023-07-11 02:23:04","level":"INFO","module":"__init__","method":"setup","line":473,"path":"C:\\Users\\yunus\\anaconda3\\lib\\site-packages\\anaconda_navigator\\widgets\\main_window\\__init__.py","message":"Initial setup"}
